[2023-10-26 14:25:04 +0000] [144114] [INFO] Starting gunicorn 21.2.0
[2023-10-26 14:25:04 +0000] [144114] [INFO] Listening at: http://0.0.0.0:8000 (144114)
[2023-10-26 14:25:04 +0000] [144114] [INFO] Using worker: sync
[2023-10-26 14:25:04 +0000] [144125] [INFO] Booting worker with pid: 144125
[2023-10-26 14:25:05 +0000] [144128] [INFO] Booting worker with pid: 144128
[2023-10-26 14:25:05 +0000] [144131] [INFO] Booting worker with pid: 144131
[2023-10-26 14:25:05 +0000] [144125] [ERROR] Exception in worker process
Traceback (most recent call last):
  File "/home/ubuntu/.local/lib/python3.8/site-packages/gunicorn/util.py", line 371, in import_app
    mod = importlib.import_module(module)
  File "/usr/lib/python3.8/importlib/__init__.py", line 127, in import_module
    return _bootstrap._gcd_import(name[level:], package, level)
  File "<frozen importlib._bootstrap>", line 1014, in _gcd_import
  File "<frozen importlib._bootstrap>", line 991, in _find_and_load
  File "<frozen importlib._bootstrap>", line 970, in _find_and_load_unlocked
ModuleNotFoundError: No module named '0-server_api.py'; '0-server_api' is not a package

During handling of the above exception, another exception occurred:

Traceback (most recent call last):
  File "/home/ubuntu/.local/lib/python3.8/site-packages/gunicorn/arbiter.py", line 609, in spawn_worker
    worker.init_process()
  File "/home/ubuntu/.local/lib/python3.8/site-packages/gunicorn/workers/base.py", line 134, in init_process
    self.load_wsgi()
  File "/home/ubuntu/.local/lib/python3.8/site-packages/gunicorn/workers/base.py", line 146, in load_wsgi
    self.wsgi = self.app.wsgi()
  File "/home/ubuntu/.local/lib/python3.8/site-packages/gunicorn/app/base.py", line 67, in wsgi
    self.callable = self.load()
  File "/home/ubuntu/.local/lib/python3.8/site-packages/gunicorn/app/wsgiapp.py", line 58, in load
    return self.load_wsgiapp()
  File "/home/ubuntu/.local/lib/python3.8/site-packages/gunicorn/app/wsgiapp.py", line 48, in load_wsgiapp
    return util.import_app(self.app_uri)
  File "/home/ubuntu/.local/lib/python3.8/site-packages/gunicorn/util.py", line 375, in import_app
    raise ImportError(msg % (module.rsplit(".", 1)[0], obj))
ImportError: Failed to find application, did you mean '0-server_api:'?
[2023-10-26 14:25:05 +0000] [144125] [INFO] Worker exiting (pid: 144125)
[2023-10-26 14:25:05 +0000] [144134] [INFO] Booting worker with pid: 144134
[2023-10-26 14:25:05 +0000] [144114] [ERROR] Worker (pid:144125) exited with code 3
[2023-10-26 14:25:05 +0000] [144128] [ERROR] Exception in worker process
Traceback (most recent call last):
  File "/home/ubuntu/.local/lib/python3.8/site-packages/gunicorn/util.py", line 371, in import_app
    mod = importlib.import_module(module)
  File "/usr/lib/python3.8/importlib/__init__.py", line 127, in import_module
    return _bootstrap._gcd_import(name[level:], package, level)
  File "<frozen importlib._bootstrap>", line 1014, in _gcd_import
  File "<frozen importlib._bootstrap>", line 991, in _find_and_load
  File "<frozen importlib._bootstrap>", line 970, in _find_and_load_unlocked
ModuleNotFoundError: No module named '0-server_api.py'; '0-server_api' is not a package

During handling of the above exception, another exception occurred:

Traceback (most recent call last):
  File "/home/ubuntu/.local/lib/python3.8/site-packages/gunicorn/arbiter.py", line 609, in spawn_worker
    worker.init_process()
  File "/home/ubuntu/.local/lib/python3.8/site-packages/gunicorn/workers/base.py", line 134, in init_process
    self.load_wsgi()
  File "/home/ubuntu/.local/lib/python3.8/site-packages/gunicorn/workers/base.py", line 146, in load_wsgi
    self.wsgi = self.app.wsgi()
  File "/home/ubuntu/.local/lib/python3.8/site-packages/gunicorn/app/base.py", line 67, in wsgi
    self.callable = self.load()
  File "/home/ubuntu/.local/lib/python3.8/site-packages/gunicorn/app/wsgiapp.py", line 58, in load
    return self.load_wsgiapp()
  File "/home/ubuntu/.local/lib/python3.8/site-packages/gunicorn/app/wsgiapp.py", line 48, in load_wsgiapp
    return util.import_app(self.app_uri)
  File "/home/ubuntu/.local/lib/python3.8/site-packages/gunicorn/util.py", line 375, in import_app
    raise ImportError(msg % (module.rsplit(".", 1)[0], obj))
ImportError: Failed to find application, did you mean '0-server_api:'?
[2023-10-26 14:25:05 +0000] [144128] [INFO] Worker exiting (pid: 144128)
[2023-10-26 14:25:05 +0000] [144131] [ERROR] Exception in worker process
Traceback (most recent call last):
  File "/home/ubuntu/.local/lib/python3.8/site-packages/gunicorn/util.py", line 371, in import_app
    mod = importlib.import_module(module)
  File "/usr/lib/python3.8/importlib/__init__.py", line 127, in import_module
    return _bootstrap._gcd_import(name[level:], package, level)
  File "<frozen importlib._bootstrap>", line 1014, in _gcd_import
  File "<frozen importlib._bootstrap>", line 991, in _find_and_load
  File "<frozen importlib._bootstrap>", line 970, in _find_and_load_unlocked
ModuleNotFoundError: No module named '0-server_api.py'; '0-server_api' is not a package

During handling of the above exception, another exception occurred:

Traceback (most recent call last):
  File "/home/ubuntu/.local/lib/python3.8/site-packages/gunicorn/arbiter.py", line 609, in spawn_worker
    worker.init_process()
  File "/home/ubuntu/.local/lib/python3.8/site-packages/gunicorn/workers/base.py", line 134, in init_process
    self.load_wsgi()
  File "/home/ubuntu/.local/lib/python3.8/site-packages/gunicorn/workers/base.py", line 146, in load_wsgi
    self.wsgi = self.app.wsgi()
  File "/home/ubuntu/.local/lib/python3.8/site-packages/gunicorn/app/base.py", line 67, in wsgi
    self.callable = self.load()
  File "/home/ubuntu/.local/lib/python3.8/site-packages/gunicorn/app/wsgiapp.py", line 58, in load
    return self.load_wsgiapp()
  File "/home/ubuntu/.local/lib/python3.8/site-packages/gunicorn/app/wsgiapp.py", line 48, in load_wsgiapp
    return util.import_app(self.app_uri)
  File "/home/ubuntu/.local/lib/python3.8/site-packages/gunicorn/util.py", line 375, in import_app
    raise ImportError(msg % (module.rsplit(".", 1)[0], obj))
ImportError: Failed to find application, did you mean '0-server_api:'?
[2023-10-26 14:25:05 +0000] [144131] [INFO] Worker exiting (pid: 144131)
[2023-10-26 14:25:05 +0000] [144134] [ERROR] Exception in worker process
Traceback (most recent call last):
  File "/home/ubuntu/.local/lib/python3.8/site-packages/gunicorn/util.py", line 371, in import_app
    mod = importlib.import_module(module)
  File "/usr/lib/python3.8/importlib/__init__.py", line 127, in import_module
    return _bootstrap._gcd_import(name[level:], package, level)
  File "<frozen importlib._bootstrap>", line 1014, in _gcd_import
  File "<frozen importlib._bootstrap>", line 991, in _find_and_load
  File "<frozen importlib._bootstrap>", line 970, in _find_and_load_unlocked
ModuleNotFoundError: No module named '0-server_api.py'; '0-server_api' is not a package

During handling of the above exception, another exception occurred:

Traceback (most recent call last):
  File "/home/ubuntu/.local/lib/python3.8/site-packages/gunicorn/arbiter.py", line 609, in spawn_worker
    worker.init_process()
  File "/home/ubuntu/.local/lib/python3.8/site-packages/gunicorn/workers/base.py", line 134, in init_process
    self.load_wsgi()
  File "/home/ubuntu/.local/lib/python3.8/site-packages/gunicorn/workers/base.py", line 146, in load_wsgi
    self.wsgi = self.app.wsgi()
  File "/home/ubuntu/.local/lib/python3.8/site-packages/gunicorn/app/base.py", line 67, in wsgi
    self.callable = self.load()
  File "/home/ubuntu/.local/lib/python3.8/site-packages/gunicorn/app/wsgiapp.py", line 58, in load
    return self.load_wsgiapp()
  File "/home/ubuntu/.local/lib/python3.8/site-packages/gunicorn/app/wsgiapp.py", line 48, in load_wsgiapp
    return util.import_app(self.app_uri)
  File "/home/ubuntu/.local/lib/python3.8/site-packages/gunicorn/util.py", line 375, in import_app
    raise ImportError(msg % (module.rsplit(".", 1)[0], obj))
ImportError: Failed to find application, did you mean '0-server_api:'?
[2023-10-26 14:25:05 +0000] [144134] [INFO] Worker exiting (pid: 144134)
[2023-10-26 14:25:05 +0000] [144114] [ERROR] Worker (pid:144128) exited with code 3
[2023-10-26 14:25:05 +0000] [144114] [ERROR] Worker (pid:144131) exited with code 3
[2023-10-26 14:25:06 +0000] [144114] [ERROR] Worker (pid:144134) exited with code 3
